2024-09-18T14:25:10.1234567Z ##[section]Starting: python -m pytest
2024-09-18T14:25:10.2345678Z ============================= test session starts ==============================
2024-09-18T14:25:10.3456789Z platform linux -- Python 3.11.0, pytest-7.4.0, pluggy-1.2.0
2024-09-18T14:25:10.4567890Z rootdir: /home/runner/work/my-project/my-project
2024-09-18T14:25:10.5678901Z collected 15 items
2024-09-18T14:25:10.6789012Z 
2024-09-18T14:25:11.7890123Z tests/test_api.py::test_user_authentication PASSED                    [  6%]
2024-09-18T14:25:12.8901234Z tests/test_api.py::test_user_registration PASSED                      [ 13%]
2024-09-18T14:25:13.9012345Z tests/test_database.py::test_connection_timeout FAILED               [ 20%]
2024-09-18T14:25:14.0123456Z 
2024-09-18T14:25:14.1234567Z =================================== FAILURES ===================================
2024-09-18T14:25:14.2345678Z _________________________ test_connection_timeout ___________________________
2024-09-18T14:25:14.3456789Z 
2024-09-18T14:25:14.4567890Z     def test_connection_timeout():
2024-09-18T14:25:14.5678901Z         with pytest.raises(TimeoutError):
2024-09-18T14:25:14.6789012Z >           db.connect(host="192.168.1.99", timeout=1)
2024-09-18T14:25:14.7890123Z E           AssertionError: TimeoutError not raised
2024-09-18T14:25:14.8901234Z 
2024-09-18T14:25:14.9012345Z tests/test_database.py:45: AssertionError
2024-09-18T14:25:15.0123456Z =========================== short test summary info ============================
2024-09-18T14:25:15.1234567Z FAILED tests/test_database.py::test_connection_timeout - AssertionError: TimeoutError not raised
2024-09-18T14:25:15.2345678Z ========================= 1 failed, 14 passed in 4.89s =========================
2024-09-18T14:25:15.3456789Z ##[error]Process completed with exit code 1.
